<?xml version="1.0" ?>
<!--Made by Jaesung Lee/ Last update: 2024-12-09-->
<robot name="kistar_hand">

  <!-- MOUNT -->
  <link name="mount">
    <inertial>
      <mass value="0.0"/>
      <origin rpy="0 0 0" xyz="0 0 0"/>
      <inertia ixx="0.0" ixy="0.0" ixz="0.0" iyy="0.0" iyz="0.0" izz="0.0"/>
    </inertial>
    <visual>
      <geometry>
        <mesh filename="meshes/kistar/mount.STL"/>
      </geometry>
      <material name="Grey">
        <color rgba="0.2 0.2 0.2 1"/>
      </material>
    </visual>
  </link>

  <!-- PALM -->
   <link name="palm">
    <inertial>
	    <mass value="15.476"/>
	    <origin rpy="0 0 0" xyz="-0.01669 0.00079 -0.02862"/>
	    <inertia ixx="0.00032705182" ixy="-0.00001050022" ixz="0.00005386046" iyy="0.00035100257" iyz="-0.00000337009" izz="0.00016323150"/>
    </inertial>
    <visual>
      <geometry>
        <mesh filename="meshes/kistar/palm02.STL"/>
      </geometry>
      <material name="Black">
        <color rgba="0 0 0 1"/>
      </material>
    </visual>
  </link>

  <!-- thumb -->
  <link name="thumb_basemotor">
    <inertial>
    	<mass value="1.904"/>
	    <origin rpy="0 0 0" xyz="0.01002 0.00044 0.00000"/>
	    <inertia ixx="0.00000107197" ixy="0.00000008151" ixz="0.00000000000" iyy="0.00000344968" iyz="0.00000000000" izz="0.00000315305"/>
    </inertial>
    <visual>
      <geometry>
        <mesh filename="meshes/kistar/thumb_basemotor.STL"/>
      </geometry>
      <material name="Grey">
        <color rgba="0.2 0.2 0.2 1"/>
      </material>
    </visual>
  </link>

  <link name="thumb_link_0">
    <inertial>
	    <mass value="2.423"/>
	    <origin rpy="0 0 0" xyz="-0.00714 0.00000 0.02081"/>
	    <inertia ixx="0.00001317338" ixy="0.00000000000" ixz="-0.00000386319" iyy="0.00001497641" iyz="0.00000000000" izz="0.00000318767"/>
    </inertial>
    <visual>
      <geometry>
        <mesh filename="meshes/kistar/thumb_link_0.STL"/>
      </geometry>
      <material name="Grey">
        <color rgba="0.2 0.2 0.2 1"/>
      </material>
    </visual>
  </link>

  <link name="thumb_link_1">
    <inertial>
	  <mass value="0.191"/>
	    <origin rpy="0 0 0" xyz="0.00043 0.00000 0.00345"/>
	    <inertia ixx="0.00000023689" ixy="0.00000000000" ixz="0.00000000784" iyy="0.00000007651" iyz="0.00000000000" izz="0.00000021019"/>
    </inertial>
    <visual>
      <geometry>
        <mesh filename="meshes/kistar/thumb_link_1.STL"/>
      </geometry>
      <material name="Grey">
        <color rgba="0.2 0.2 0.2 1"/>
      </material>
    </visual>
  </link>

  <link name="thumb_link_2">
    <inertial>
	    <mass value="1.827"/>
	    <origin rpy="0 0 0" xyz="-0.00154 0.00021 0.01842"/>
	    <inertia ixx="0.00000796138" ixy="-0.00000001114" ixz="-0.00000053085" iyy="0.00000752132" iyz="0.00000001719" izz="0.00000105696"/>
    </inertial>
    <visual>
      <geometry>
        <mesh filename="meshes/kistar/thumb_link_2.STL"/>
      </geometry>
      <material name="Grey">
        <color rgba="0.2 0.2 0.2 1"/>
      </material>
    </visual>
  </link>

  <link name="thumb_tip">
    <inertial>
	    <mass value="0.719"/>
	    <origin rpy="0 0 0" xyz="-0.00190 0.00000 0.01626"/>
	    <inertia ixx="0.00000240986" ixy="0.00000000000" ixz="-0.00000023287" iyy="0.00000235111" iyz="0.00000000000" izz="0.00000036696"/>
    </inertial>
    <visual>
      <geometry>
        <mesh filename="meshes/kistar/thumb_tip.STL"/>
      </geometry>
      <material name="Grey">
        <color rgba="0.2 0.2 0.2 1"/>
      </material>
    </visual>
  </link>

  <link name="thumb_sensor_0">
    <inertial>
      <mass value="0.0"/>
      <origin rpy="0 0 0" xyz="0 0 0"/>
      <inertia ixx="0.0" ixy="0.0" ixz="0.0" iyy="0.0" iyz="0.0" izz="0.0"/>
    </inertial>
    <visual>
      <geometry>
        <mesh filename="meshes/kistar/sensor.STL"/>
      </geometry>
      <material name="White">
        <color rgba="1 1 1 1"/>
      </material>
    </visual>
  </link>

  <link name="thumb_sensor_1">
    <inertial>
      <mass value="0.0"/>
      <origin rpy="0 0 0" xyz="0 0 0"/>
      <inertia ixx="0.0" ixy="0.0" ixz="0.0" iyy="0.0" iyz="0.0" izz="0.0"/>
    </inertial>
    <visual>
      <geometry>
        <mesh filename="meshes/kistar/sensor.STL"/>
      </geometry>
      <material name="White">
        <color rgba="1 1 1 1"/>
      </material>
    </visual>
  </link>
 


  <!-- INDEX -->
  <link name="index_basemotor">
    <inertial>
    	<mass value="1.904"/>
    	<origin rpy="0 0 0" xyz="0.01338 0.00095 -0.00207"/>
    	<inertia ixx="0.00000121099" ixy="0.00000030359" ixz="-0.00000056482" iyy="0.00000548403" iyz="-0.00000003164" izz="0.00000507172"/>
    </inertial>
    <visual>
      <geometry>
        <mesh filename="meshes/kistar/finger_basemotor.STL"/>
      </geometry>
      <material name="Grey">
        <color rgba="0.2 0.2 0.2 1"/>
      </material>
    </visual>
  </link>

  <link name="index_link_0">
     <inertial>
	    <mass value="0.473"/>
	    <origin rpy="0 0 0" xyz="-0.00353 0.00000 0.00948"/>
	    <inertia ixx="0.00000076951" ixy="0.00000000000" ixz="-0.00000009858" iyy="0.00000092515" iyz="0.00000000000" izz="0.00000062017"/>
    </inertial>
    <visual>
      <geometry>
        <mesh filename="meshes/kistar/finger_link_0.STL"/>
      </geometry>
      <material name="Grey">
        <color rgba="0.2 0.2 0.2 1"/>
      </material>
    </visual>
  </link>

  <link name="index_link_1">
    <inertial>
	    <mass value="3.549"/>
	    <origin rpy="0 0 0" xyz="-0.00166 0.00000 0.01675"/>
	    <inertia ixx="0.00001607025" ixy="0.00000000000" ixz="-0.00000098913" iyy="0.00001510746" iyz="0.00000000000" izz="0.00000219008"/>
    </inertial>
    <visual>
      <geometry>
        <mesh filename="meshes/kistar/finger_link_1.STL"/>
      </geometry>
      <material name="Grey">
        <color rgba="0.2 0.2 0.2 1"/>
      </material>
    </visual>
  </link>

  <link name="index_link_2">
    <inertial>
	    <mass value="1.827"/>
	    <origin rpy="0 0 0" xyz="-0.00154 0.00021 0.01842"/>
	    <inertia ixx="0.00000796138" ixy="-0.00000001114" ixz="-0.00000053085" iyy="0.00000752132" iyz="0.00000001719" izz="0.00000105696"/>
    </inertial>
    <visual>
      <geometry>
        <mesh filename="meshes/kistar/finger_link_2.STL"/>
      </geometry>
      <material name="Grey">
        <color rgba="0.2 0.2 0.2 1"/>
      </material>
    </visual>
  </link>

  <link name="index_tip">
    <inertial>
	    <mass value="0.719"/>
	    <origin rpy="0 0 0" xyz="-0.00190 0.00000 0.01626"/>
	    <inertia ixx="0.00000240986" ixy="0.00000000000" ixz="-0.00000023287" iyy="0.00000235111" iyz="0.00000000000" izz="0.00000036696"/>
    </inertial>
    <visual>
      <geometry>
        <mesh filename="meshes/kistar/finger_tip.STL"/>
      </geometry>
      <material name="Grey">
        <color rgba="0.2 0.2 0.2 1"/>
      </material>
    </visual>
  </link>

  <link name="index_sensor_0">
    <inertial>
      <mass value="0.0"/>
      <origin rpy="0 0 0" xyz="0 0 0"/>
      <inertia ixx="0.0" ixy="0.0" ixz="0.0" iyy="0.0" iyz="0.0" izz="0.0"/>
    </inertial>
    <visual>
      <geometry>
        <mesh filename="meshes/kistar/sensor.STL"/>
      </geometry>
      <material name="White">
        <color rgba="1 1 1 1"/>
      </material>
    </visual>
  </link>

  <link name="index_sensor_1">
    <inertial>
      <mass value="0.0"/>
      <origin rpy="0 0 0" xyz="0 0 0"/>
      <inertia ixx="0.0" ixy="0.0" ixz="0.0" iyy="0.0" iyz="0.0" izz="0.0"/>
    </inertial>
    <visual>
      <geometry>
        <mesh filename="meshes/kistar/sensor.STL"/>
      </geometry>
      <material name="White">
        <color rgba="1 1 1 1"/>
      </material>
    </visual>
  </link>
 
  <link name="index_sensor_2">
    <inertial>
      <mass value="0.0"/>
      <origin rpy="0 0 0" xyz="0 0 0"/>
      <inertia ixx="0.0" ixy="0.0" ixz="0.0" iyy="0.0" iyz="0.0" izz="0.0"/>
    </inertial>
    <visual>
      <geometry>
        <mesh filename="meshes/kistar/sensor.STL"/>
      </geometry>
      <material name="White">
        <color rgba="1 1 1 1"/>
      </material>
    </visual>
  </link>

  <!-- Middle -->
  <link name="middle_basemotor">
    <inertial>
    	<mass value="1.904"/>
    	<origin rpy="0 0 0" xyz="0.01338 0.00095 -0.00207"/>
    	<inertia ixx="0.00000121099" ixy="0.00000030359" ixz="-0.00000056482" iyy="0.00000548403" iyz="-0.00000003164" izz="0.00000507172"/>
    </inertial>
    <visual>
      <geometry>
        <mesh filename="meshes/kistar/finger_basemotor.STL"/>
      </geometry>
      <material name="Grey">
        <color rgba="0.2 0.2 0.2 1"/>
      </material>
    </visual>
  </link>

  <link name="middle_link_0">
     <inertial>
	    <mass value="0.473"/>
	    <origin rpy="0 0 0" xyz="-0.00353 0.00000 0.00948"/>
	    <inertia ixx="0.00000076951" ixy="0.00000000000" ixz="-0.00000009858" iyy="0.00000092515" iyz="0.00000000000" izz="0.00000062017"/>
    </inertial>
    <visual>
      <geometry>
        <mesh filename="meshes/kistar/finger_link_0.STL"/>
      </geometry>
      <material name="Grey">
        <color rgba="0.2 0.2 0.2 1"/>
      </material>
    </visual>
  </link>

  <link name="middle_link_1">
    <inertial>
	    <mass value="3.549"/>
	    <origin rpy="0 0 0" xyz="-0.00166 0.00000 0.01675"/>
	    <inertia ixx="0.00001607025" ixy="0.00000000000" ixz="-0.00000098913" iyy="0.00001510746" iyz="0.00000000000" izz="0.00000219008"/>
    </inertial>
    <visual>
      <geometry>
        <mesh filename="meshes/kistar/finger_link_1.STL"/>
      </geometry>
      <material name="Grey">
        <color rgba="0.2 0.2 0.2 1"/>
      </material>
    </visual>
  </link>

  <link name="middle_link_2">
    <inertial>
	    <mass value="1.827"/>
	    <origin rpy="0 0 0" xyz="-0.00154 0.00021 0.01842"/>
	    <inertia ixx="0.00000796138" ixy="-0.00000001114" ixz="-0.00000053085" iyy="0.00000752132" iyz="0.00000001719" izz="0.00000105696"/>
    </inertial>
    <visual>
      <geometry>
        <mesh filename="meshes/kistar/finger_link_2.STL"/>
      </geometry>
      <material name="Grey">
        <color rgba="0.2 0.2 0.2 1"/>
      </material>
    </visual>
  </link>

  <link name="middle_tip">
    <inertial>
	    <mass value="0.719"/>
	    <origin rpy="0 0 0" xyz="-0.00190 0.00000 0.01626"/>
	    <inertia ixx="0.00000240986" ixy="0.00000000000" ixz="-0.00000023287" iyy="0.00000235111" iyz="0.00000000000" izz="0.00000036696"/>
    </inertial>
    <visual>
      <geometry>
        <mesh filename="meshes/kistar/finger_tip.STL"/>
      </geometry>
      <material name="Grey">
        <color rgba="0.2 0.2 0.2 1"/>
      </material>
    </visual>
  </link>

  <link name="middle_sensor_0">
    <inertial>
      <mass value="0.0"/>
      <origin rpy="0 0 0" xyz="0 0 0"/>
      <inertia ixx="0.0" ixy="0.0" ixz="0.0" iyy="0.0" iyz="0.0" izz="0.0"/>
    </inertial>
    <visual>
      <geometry>
        <mesh filename="meshes/kistar/sensor.STL"/>
      </geometry>
      <material name="White">
        <color rgba="1 1 1 1"/>
      </material>
    </visual>
  </link>

  <link name="middle_sensor_1">
    <inertial>
      <mass value="0.0"/>
      <origin rpy="0 0 0" xyz="0 0 0"/>
      <inertia ixx="0.0" ixy="0.0" ixz="0.0" iyy="0.0" iyz="0.0" izz="0.0"/>
    </inertial>
    <visual>
      <geometry>
        <mesh filename="meshes/kistar/sensor.STL"/>
      </geometry>
      <material name="White">
        <color rgba="1 1 1 1"/>
      </material>
    </visual>
  </link>
 
  <link name="middle_sensor_2">
    <inertial>
      <mass value="0.0"/>
      <origin rpy="0 0 0" xyz="0 0 0"/>
      <inertia ixx="0.0" ixy="0.0" ixz="0.0" iyy="0.0" iyz="0.0" izz="0.0"/>
    </inertial>
    <visual>
      <geometry>
        <mesh filename="meshes/kistar/sensor.STL"/>
      </geometry>
      <material name="White">
        <color rgba="1 1 1 1"/>
      </material>
    </visual>
  </link>


  <!-- RING -->
  <link name="ring_basemotor">
    <inertial>
    	<mass value="1.904"/>
    	<origin rpy="0 0 0" xyz="0.01338 0.00095 -0.00207"/>
    	<inertia ixx="0.00000121099" ixy="0.00000030359" ixz="-0.00000056482" iyy="0.00000548403" iyz="-0.00000003164" izz="0.00000507172"/>
    </inertial>
    <visual>
      <geometry>
        <mesh filename="meshes/kistar/finger_basemotor.STL"/>
      </geometry>
      <material name="Grey">
        <color rgba="0.2 0.2 0.2 1"/>
      </material>
    </visual>
  </link>

  <link name="ring_link_0">
    <inertial>
	    <mass value="0.473"/>
	    <origin rpy="0 0 0" xyz="-0.00353 0.00000 0.00948"/>
	    <inertia ixx="0.00000076951" ixy="0.00000000000" ixz="-0.00000009858" iyy="0.00000092515" iyz="0.00000000000" izz="0.00000062017"/>
    </inertial>
    <visual>
      <geometry>
        <mesh filename="meshes/kistar/finger_link_0.STL"/>
      </geometry>
      <material name="Grey">
        <color rgba="0.2 0.2 0.2 1"/>
      </material>
    </visual>
  </link>

  <link name="ring_link_1">
    <inertial>
	    <mass value="3.549"/>
	    <origin rpy="0 0 0" xyz="-0.00166 0.00000 0.01675"/>
	    <inertia ixx="0.00001607025" ixy="0.00000000000" ixz="-0.00000098913" iyy="0.00001510746" iyz="0.00000000000" izz="0.00000219008"/>
    </inertial>
    <visual>
      <geometry>
        <mesh filename="meshes/kistar/finger_link_1.STL"/>
      </geometry>
      <material name="Grey">
        <color rgba="0.2 0.2 0.2 1"/>
      </material>
    </visual>
  </link>

  <link name="ring_link_2">
    <inertial>
	    <mass value="1.827"/>
	    <origin rpy="0 0 0" xyz="-0.00154 0.00021 0.01842"/>
	    <inertia ixx="0.00000796138" ixy="-0.00000001114" ixz="-0.00000053085" iyy="0.00000752132" iyz="0.00000001719" izz="0.00000105696"/>
    </inertial>
    <visual>
      <geometry>
        <mesh filename="meshes/kistar/finger_link_2.STL"/>
      </geometry>
      <material name="Grey">
        <color rgba="0.2 0.2 0.2 1"/>
      </material>
    </visual>
  </link>

  <link name="ring_tip">
    <inertial>
	    <mass value="0.719"/>
	    <origin rpy="0 0 0" xyz="-0.00190 0.00000 0.01626"/>
	    <inertia ixx="0.00000240986" ixy="0.00000000000" ixz="-0.00000023287" iyy="0.00000235111" iyz="0.00000000000" izz="0.00000036696"/>
    </inertial>
    <visual>
      <geometry>
        <mesh filename="meshes/kistar/finger_tip.STL"/>
      </geometry>
      <material name="Grey">
        <color rgba="0.2 0.2 0.2 1"/>
      </material>
    </visual>
  </link>

  <link name="ring_sensor_0">
    <inertial>
      <mass value="0.0"/>
      <origin rpy="0 0 0" xyz="0 0 0"/>
      <inertia ixx="0.0" ixy="0.0" ixz="0.0" iyy="0.0" iyz="0.0" izz="0.0"/>
    </inertial>
    <visual>
      <geometry>
        <mesh filename="meshes/kistar/sensor.STL"/>
      </geometry>
      <material name="White">
        <color rgba="1 1 1 1"/>
      </material>
    </visual>
  </link>

  <link name="ring_sensor_1">
    <inertial>
      <mass value="0.0"/>
      <origin rpy="0 0 0" xyz="0 0 0"/>
      <inertia ixx="0.0" ixy="0.0" ixz="0.0" iyy="0.0" iyz="0.0" izz="0.0"/>
    </inertial>
    <visual>
      <geometry>
        <mesh filename="meshes/kistar/sensor.STL"/>
      </geometry>
      <material name="White">
        <color rgba="1 1 1 1"/>
      </material>
    </visual>
  </link>
 
  <link name="ring_sensor_2">
    <inertial>
      <mass value="0.0"/>
      <origin rpy="0 0 0" xyz="0 0 0"/>
      <inertia ixx="0.0" ixy="0.0" ixz="0.0" iyy="0.0" iyz="0.0" izz="0.0"/>
    </inertial>
    <visual>
      <geometry>
        <mesh filename="meshes/kistar/sensor.STL"/>
      </geometry>
      <material name="White">
        <color rgba="1 1 1 1"/>
      </material>
    </visual>
  </link>


<!-- MOUNT JOINT -->
<joint name="kistar_mount_joint" type="fixed">
  <origin rpy="0. 0. 0." xyz="-0.02325 0. 0.071"/>
  <parent link="mount"/>
  <child link="palm"/>
</joint>


 <!-- THUMB JOINT -->
 <joint name="thumb_base_joint" type="fixed">
  <origin rpy="-0.0873 0. 0." xyz="0. 0.01224 -0.02988"/>
  <parent link="palm"/>
  <child link="thumb_basemotor"/>
</joint>

<joint name="thumb_joint_0" type="revolute">
  <axis xyz="0 1 0"/>
  <limit effort="10.0" lower="0." upper="1.5708" velocity="6.283"/>
  <origin rpy="-1.5708 0. 0." xyz="0.0197 0.002 0."/>
  <parent link="thumb_basemotor"/>
  <child link="thumb_link_0"/>
  <dynamics damping="0.0414019" friction="0.0523963"/>
</joint>

<joint name="thumb_joint_1" type="revolute">
  <axis xyz="0 0 1"/>
  <limit effort="10.0" lower="-1.5708" upper="0.15708" velocity="6.283"/>
  <origin rpy="0. 0. 0." xyz="-0.002 0. 0.036"/>
  <parent link="thumb_link_0"/>
  <child link="thumb_link_1"/>
  <dynamics damping="0.00587541" friction="0.0150275"/>
</joint>
<joint name="thumb_joint_2" type="revolute">
  <axis xyz="0 1 0"/>
  <limit effort="10.0" lower="0" upper="1.5708" velocity="6.283"/>
  <origin rpy="0. 0. 0." xyz="0.002 0. 0.0102"/>
  <parent link="thumb_link_1"/>
  <child link="thumb_link_2"/>
  <dynamics damping="0.010638" friction="0.00616359"/>
</joint>
<joint name="thumb_joint_3" type="revolute">
  <axis xyz="0 1 0"/>
  <limit effort="10.0" lower="0" upper="1.5708" velocity="6.283"/>
  <origin rpy="0. 0. 0." xyz="0. 0. 0.0335"/>
  <parent link="thumb_link_2"/>
  <child link="thumb_tip"/>
  <dynamics damping="0.0226948" friction="0.0227036"/>
</joint>

<joint name="thumb_sensor_0" type="fixed">
  <origin rpy="0. 0. 0." xyz="0.00525 0. 0.00865"/>
  <parent link="thumb_link_2"/>
  <child link="thumb_sensor_0"/>
</joint>

<joint name="thumb_sensor_1" type="fixed">
  <origin rpy="0. 0. 0." xyz="0.00525 0. 0.02485"/>
  <parent link="thumb_link_2"/>
  <child link="thumb_sensor_1"/>
</joint>

<!-- INDEX JOINT -->
<joint name="index_base_joint" type="fixed">
  <origin rpy="-0.0873 0. 0." xyz="0. 0.02883 -0.00126"/>
  <parent link="palm"/>
  <child link="index_basemotor"/>
</joint>

<joint name="index_joint_0" type="revolute">
  <axis xyz="1 0 0"/>
  <limit effort="10.0" lower="-0.261799" upper="0.08" velocity="6.283"/>
  <origin rpy="-0. 0. 0." xyz="0.02325 0. 0.0047"/>
  <parent link="index_basemotor"/>
  <child link="index_link_0"/>
  <dynamics damping="0.0414019" friction="0.0523963"/>
</joint>
<joint name="index_joint_1" type="revolute">
  <axis xyz="0 1 0"/>
  <limit effort="10.0" lower="0" upper="1.5708" velocity="6.283"/>
  <origin rpy="0. 0. 0." xyz="0.002 0. 0.019"/>
  <parent link="index_link_0"/>
  <child link="index_link_1"/>
  <dynamics damping="0.00587541" friction="0.0150275"/>
</joint>
<joint name="index_joint_2" type="revolute">
  <axis xyz="0 1 0"/>
  <limit effort="10.0" lower="0" upper="1.5708" velocity="6.283"/>
  <origin rpy="0. 0. 0." xyz="0. 0. 0.0335"/>
  <parent link="index_link_1"/>
  <child link="index_link_2"/>
  <dynamics damping="0.010638" friction="0.00616359"/>
</joint>
<joint name="index_joint_3" type="revolute">
  <axis xyz="0 1 0"/>
  <limit effort="10.0" lower="0" upper="1.5708" velocity="6.283"/>
  <origin rpy="0. 0. 0." xyz="0. 0. 0.0267"/>
  <parent link="index_link_2"/>
  <child link="index_tip"/>
  <dynamics damping="0.0226948" friction="0.0227036"/>
</joint>

<joint name="index_sensor_0" type="fixed">
  <origin rpy="0. 0. 0." xyz="0.00525 0. 0.00865"/>
  <parent link="index_link_1"/>
  <child link="index_sensor_0"/>
</joint>

<joint name="index_sensor_1" type="fixed">
  <origin rpy="0. 0. 0." xyz="0.00525 0. 0.02485"/>
  <parent link="index_link_1"/>
  <child link="index_sensor_1"/>
</joint>

<joint name="index_sensor_2" type="fixed">
  <origin rpy="0. 0. 0." xyz="0.00525 0. 0.01805"/>
  <parent link="index_link_2"/>
  <child link="index_sensor_2"/>
</joint>


<!-- MIDDLE JOINT -->

<joint name="middle_base_joint" type="fixed">
  <origin rpy="0. 0. 0." xyz="0. 0. 0."/>
  <parent link="palm"/>
  <child link="middle_basemotor"/>
</joint>

<joint name="middle_joint_0" type="revolute">
  <axis xyz="1 0 0"/>
  <limit effort="10.0" lower="-0.261799" upper="0.261799" velocity="6.283"/>
  <origin rpy="0. 0. 0." xyz="0.02325 0. 0.0047"/>
  <parent link="middle_basemotor"/>
  <child link="middle_link_0"/>
  <dynamics damping="0.0414019" friction="0.0523963"/>
</joint>

<joint name="middle_joint_1" type="revolute">
  <axis xyz="0 1 0"/>
  <limit effort="10.0" lower="0" upper="1.5708" velocity="6.283"/>
  <origin rpy="0. 0. 0." xyz="0.002 0. 0.019"/>
  <parent link="middle_link_0"/>
  <child link="middle_link_1"/>
  <dynamics damping="0.00587541" friction="0.0150275"/>
</joint>

<joint name="middle_joint_2" type="revolute">
  <axis xyz="0 1 0"/>
  <limit effort="10.0" lower="0" upper="1.5708" velocity="6.283"/>
  <origin rpy="0 0 0" xyz="0. 0. 0.0335"/>
  <parent link="middle_link_1"/>
  <child link="middle_link_2"/>
  <dynamics damping="0.010638" friction="0.00616359"/>
</joint>

<joint name="middle_joint_3" type="revolute">
  <axis xyz="0 1 0"/>
  <limit effort="10.0" lower="0" upper="1.5708" velocity="6.283"/>
  <origin rpy="0 0 0" xyz="0. 0. 0.0267"/>
  <parent link="middle_link_2"/>
  <child link="middle_tip"/>
  <dynamics damping="0.0226948" friction="0.0227036"/>
</joint>

<joint name="middle_sensor_0" type="fixed">
  <origin rpy="0. 0. 0." xyz="0.00525 0. 0.00865"/>
  <parent link="middle_link_1"/>
  <child link="middle_sensor_0"/>
</joint>

<joint name="middle_sensor_1" type="fixed">
  <origin rpy="0. 0. 0." xyz="0.00525 0. 0.02485"/>
  <parent link="middle_link_1"/>
  <child link="middle_sensor_1"/>
</joint>

<joint name="middle_sensor_2" type="fixed">
  <origin rpy="0. 0. 0." xyz="0.00525 0. 0.01805"/>
  <parent link="middle_link_2"/>
  <child link="middle_sensor_2"/>
</joint>


 <!-- RING JOINT -->
<joint name="ring_base_joint" type="fixed">
  <origin rpy="0.0873 0. 0." xyz="0. -0.02883 -0.00126"/>
  <parent link="palm"/>
  <child link="ring_basemotor"/>
</joint>

<joint name="ring_joint_0" type="revolute">
  <axis xyz="1 0 0"/>
  <limit effort="10.0" lower="-0.08" upper="0.261799" velocity="6.283"/>
  <origin rpy="-0. 0. 0." xyz="0.02325 0. 0.0047"/>
  <parent link="ring_basemotor"/>
  <child link="ring_link_0"/>
  <dynamics damping="0.0414019" friction="0.0523963"/>
</joint>
<joint name="ring_joint_1" type="revolute">
  <axis xyz="0 1 0"/>
  <limit effort="10.0" lower="0" upper="1.5708" velocity="6.283"/>
  <origin rpy="0. 0. 0." xyz="0.002 0. 0.019"/>
  <parent link="ring_link_0"/>
  <child link="ring_link_1"/>
  <dynamics damping="0.00587541" friction="0.0150275"/>
</joint>
<joint name="ring_joint_2" type="revolute">
  <axis xyz="0 1 0"/>
  <limit effort="10.0" lower="0" upper="1.5708" velocity="6.283"/>
  <origin rpy="0. 0. 0." xyz="0. 0. 0.0335"/>
  <parent link="ring_link_1"/>
  <child link="ring_link_2"/>
  <dynamics damping="0.010638" friction="0.00616359"/>
</joint>
<joint name="ring_joint_3" type="revolute">
  <axis xyz="0 1 0"/>
  <limit effort="10.0" lower="0" upper="1.5708" velocity="6.283"/>
  <origin rpy="0. 0. 0." xyz="0. 0. 0.0267"/>
  <parent link="ring_link_2"/>
  <child link="ring_tip"/>
  <dynamics damping="0.0226948" friction="0.0227036"/>
</joint>

<joint name="ring_sensor_0" type="fixed">
  <origin rpy="0. 0. 0." xyz="0.00525 0. 0.00865"/>
  <parent link="ring_link_1"/>
  <child link="ring_sensor_0"/>
</joint>

<joint name="ring_sensor_1" type="fixed">
  <origin rpy="0. 0. 0." xyz="0.00525 0. 0.02485"/>
  <parent link="ring_link_1"/>
  <child link="ring_sensor_1"/>
</joint>

<joint name="ring_sensor_2" type="fixed">
  <origin rpy="0. 0. 0." xyz="0.00525 0. 0.01805"/>
  <parent link="ring_link_2"/>
  <child link="ring_sensor_2"/>
</joint>



<link name="thumb_tip_end"/>
<link name="index_tip_end"/>
<link name="middle_tip_end"/>
<link name="ring_tip_end"/>

<joint name="thumb_joint_end" type="fixed">
  <origin rpy="0. 0. 0." xyz="0. 0. 0.030"/>
  <parent link="thumb_tip"/>
  <child link="thumb_tip_end"/>
</joint>
<joint name="index_joint_end" type="fixed">
  <origin rpy="0. 0. 0." xyz="0. 0. 0.030"/>
  <parent link="index_tip"/>
  <child link="index_tip_end"/>
</joint>
<joint name="middle_joint_end" type="fixed">
  <origin rpy="0. 0. 0." xyz="0. 0. 0.030"/>
  <parent link="middle_tip"/>
  <child link="middle_tip_end"/>
</joint>
<joint name="ring_joint_end" type="fixed">
  <origin rpy="0. 0. 0." xyz="0. 0. 0.030"/>
  <parent link="ring_tip"/>
  <child link="ring_tip_end"/>
</joint>

</robot>